Workbook
Name Slicer_Status: #N/A

Sheet Dashboard
D2: Payment Summary | R2: =TODAY() -> 46232
B3: EXECUTIVE DASHBOARD | D3: R06-HW2C05 · SHURA WEST HOTEL 02 · FIRST FIX | R3: ="REF: "&'Payment Register'!A46&" · COMMERCIAL TEAM FFC" -> REF: IPA 28 · COMMERCIAL TEAM FFC
B6: I. | C6: Contract & Progress
B8: ORIGINAL CONTRACT | G8: REVISED CONTRACT | J8: ="+"&TEXT(('Payment Register'!D5-217501556.12)/217501556.12,"0.00%")&" vs ORIGINAL" -> +7.06% vs ORIGINAL | L8: TOTAL APPROVED WORK DONE | O8: ='Payment Register'!E12 -> 0.95356091 | Q8: BALANCE TO COMPLETE | T8: =1-'Payment Register'!E12 -> 0.046439086
B9: 2.1750156e+08 | G9: ='Payment Register'!D5 -> 2.328609e+08 | L9: ='Payment Register'!D12 -> 2.2204706e+08 | Q9: ='Payment Register'!D13 -> 10813848
B10: SAR | G10: SAR · UPLIFT vs ORIGINAL | L10: SAR · GROSS CLAIMED | Q10: SAR · GROSS
B12: II. | C12: Work & Payment Progress | L12: III. | M12: Variation Orders
B14: STATUS | F14: % | G14: GROSS (SAR) | I14: NET (SAR) | L14: STATUS | Q14: COUNT | S14: AMOUNT (SAR)
B15: Total Work Done | F15: ='Payment Register'!E12 -> 0.95356091 | G15: ='Payment Register'!D12 -> 2.2204706e+08 | I15: ='Payment Summary'!G20 -> 1.6565143e+08 | L15: Total Submitted VO | Q15: =Sheet1!D7 -> 74 | S15: =Sheet1!E7 -> 25035632
B16: Received | F16: ='Payment Register'!E10 -> 0.93965367 | G16: ='Payment Register'!D10 -> 2.188086e+08 | I16: ='Payment Summary'!G21 -> 1.6565143e+08 | L16: Pending with FFC | Q16: =Sheet1!$D$1 -> 9 | S16: =Sheet1!$E$1 -> 0
B17: Approved via ACONEX | F17: ='Payment Register'!E9 -> 0.013907242 | G17: ='Payment Register'!D9 -> 3238453.1 | I17: ='Payment Summary'!G22 -> 0 | L17: Pending with RSG | Q17: =Sheet1!$D$2 -> 22 | S17: =Sheet1!$E$2 -> 2991535.6
B18: Submitted in ACONEX | F18: ='Payment Register'!E8 -> 0 | G18: ='Payment Register'!D8 -> 0 | I18: ='Payment Summary'!G23 -> 0 | L18: Pending with RSG/FFC | Q18: =Sheet1!$D$3 -> 4 | S18: =Sheet1!$E$3 -> 6684748.2
B19: Under Review | F19: ='Payment Register'!E7 -> 0.011579357 | G19: ='Payment Register'!D7 -> 2696379.6 | I19: ='Payment Summary'!G24 -> 0 | L19: Approved & Awaiting DVO | Q19: =Sheet1!$D$4 -> 18 | S19: =Sheet1!$E$4 -> -23074.749
B20: Balance to Complete | F20: =1-'Payment Register'!E12 -> 0.046439086 | G20: ='Payment Register'!D13 -> 10813848 | L20: DVO RR Issued | Q20: =Sheet1!$D$5 -> 8 | S20: =Sheet1!$E$5 -> -362299.97
B22: IV. | C22: Advance Payment | L22: V. | M22: Retention
B24: TOTAL ADVANCE | E24: ='Payment Register'!I4 -> 0.3209 | L24: TOTAL RETENTION | O24: 5.0% rate
B25: 65250467 | L25: ='Payment Register'!H9 -> 11643045
B26: SAR | L26: SAR
B28: DEDUCTED | E28: % | L28: DEDUCTED | O28: %
B29: ='Payment Register'!H5 -> 65250467 | E29: ='Payment Register'!I5 -> 1 | L29: ='Payment Register'!H10 -> 11102353 | O29: ='Payment Register'!I10 -> 0.95356091
B31: BALANCE | E31: % | L31: BALANCE | O31: %
B32: ='Payment Register'!H6 -> 0.030560583 | E32: =1-'Payment Register'!I5 -> 4.6835802e-10 | L32: ='Payment Register'!H11 -> 540692.4 | O32: ='Payment Register'!I11 -> 0.046439088
D34: Executive Dashboard · Internal use only | R34: ="REF: "&'Payment Register'!A46&" · COMMERCIAL TEAM FFC · ALL VALUES IN SAR" -> REF: IPA 28 · COMMERCIAL TEAM FFC · ALL VALUES IN SAR

Sheet Payment Summary
N1: Chart Data (hidden)
B2: Commercial Payment Summary | J2: =TODAY() -> 46232 | N2: Work Progress | O2: Label | P2: Value
B3: COMMERCIAL | C3: R06-HW2C05 · SHURA WEST HOTEL 02 · FIRST FIX | J3: ="REF: "&'Payment Register'!A46&" · COMMERCIAL TEAM FFC" -> REF: IPA 28 · COMMERCIAL TEAM FFC | N3: Completed | O3: Completed | P3: ='Payment Register'!E12 -> 0.95356091
N4: Remaining | O4: Remaining | P4: =1-'Payment Register'!E12 -> 0.046439086
B6: I. | C6: Contract Overview | J6: IV. | K6: Advance Payment | N6: Advance | O6: Deducted | P6: ='Payment Register'!I5 -> 1
O7: Balance | P7: =1-'Payment Register'!I5 -> 4.6835802e-10
C8: ORIGINAL CONTRACT VALUE | E8: REVISED CONTRACT VALUE | F8: VARIANCE | J8: TOTAL ADVANCE
C9: ='Payment Register'!D4 -> 2.1750156e+08 | E9: ='Payment Register'!D5 -> 2.328609e+08 | F9: =(E9-C9)/C9 -> 0.070617186 | J9: ='Payment Register'!H4 -> 65250467 | K9: ='Payment Register'!I4 -> 0.3209 | N9: Retention | O9: Deducted | P9: ='Payment Register'!I10 -> 0.95356091
C10: SAR | E10: SAR | F10: UPLIFT vs ORIGINAL | J10: SAR | O10: Balance | P10: ='Payment Register'!I11 -> 0.046439088
B12: II. | C12: Work & Payment Progress | J12: DEDUCTED | K12: % | N12: VO Status
J13: ='Payment Register'!H5 -> 65250467 | K13: ='Payment Register'!I5 -> 1 | O13: Pending FFC | P13: =#REF! -> #REF!
C14: TOTAL CLAIMED (GROSS) | F14: BALANCE (GROSS) | O14: Pending RSG | P14: =#REF! -> #REF!
C15: ='Payment Register'!D12 -> 2.2204706e+08 | F15: ='Payment Register'!D13 -> 10813848 | J15: BALANCE | K15: % | O15: Pending RSG/FFC | P15: =#REF! -> #REF!
C16: =TEXT('Payment Register'!E12,"0.0%")&" of revised contract complete" -> 95.4% of revised contract complete | F16: =TEXT(1-'Payment Register'!E12,"0.0%")&" remaining" -> 4.6% remaining | J16: ='Payment Register'!H6 -> 0.030560583 | K16: =1-'Payment Register'!I5 -> 4.6835802e-10 | O16: Approved/Awaiting DVO | P16: =#REF! -> #REF!
O17: DVO RR Issued | P17: =#REF! -> #REF!
J18: V. | K18: Retention
C19: STATUS | E19: % COMPLETE | F19: GROSS (SAR) | G19: NET (SAR)
C20: Total Work Done | E20: ='Payment Register'!E12 -> 0.95356091 | F20: ='Payment Register'!D12 -> 2.2204706e+08 | G20: =SUM('Payment Register'!J19:J46) -> 1.6565143e+08 | J20: TOTAL RETENTION
C21: Received | E21: ='Payment Register'!E10 -> 0.93965367 | F21: ='Payment Register'!D10 -> 2.188086e+08 | G21: =SUMIFS('Payment Register'!J19:J46,'Payment Register'!Q19:Q46,"Received") -> 1.6565143e+08 | J21: ='Payment Register'!H9 -> 11643045 | K21: ='Payment Register'!I9 -> 0.05
C22: Approved via ACONEX | E22: ='Payment Register'!E9 -> 0.013907242 | F22: ='Payment Register'!D9 -> 3238453.1 | G22: =SUMIFS('Payment Register'!J19:J46,'Payment Register'!Q19:Q46,'Payment Register'!X19) -> 0 | J22: SAR
C23: Submitted in ACONEX | E23: ='Payment Register'!E8 -> 0 | F23: ='Payment Register'!D8 -> 0 | G23: =SUMIFS('Payment Register'!J19:J46,'Payment Register'!Q19:Q46,'Payment Register'!X20) -> 0
C24: Under Review | E24: ='Payment Register'!E7 -> 0.011579357 | F24: ='Payment Register'!D7 -> 2696379.6 | G24: =SUMIFS('Payment Register'!J19:J46,'Payment Register'!Q19:Q46,'Payment Register'!X21) -> 0 | J24: DEDUCTED | K24: %
C25: Balance to Complete | E25: =1-'Payment Register'!E12 -> 0.046439086 | F25: ='Payment Register'!D13 -> 10813848 | G25: =(E9-F20)*1.1 -> 11895232 | J25: ='Payment Register'!H10 -> 11102353 | K25: ='Payment Register'!I10 -> 0.95356091
B27: III. | C27: Variation Orders | J27: BALANCE | K27: %
J28: ='Payment Register'!H11 -> 540692.4 | K28: ='Payment Register'!I11 -> 0.046439088
C29: TO BE ADDED IN CONTRACT | F29: TOTAL SUBMITTED VO VALUE
C30: =F38+F37 -> -385374.72 | F30: =F39 -> 25035632
C31: APPROVED + DVO ISSUED · SAR | F31: =#REF!&" VOs TRACKED" -> #REF!
C33: STATUS | E33: COUNT | F33: AMOUNT (SAR)
C34: Pending with FFC | E34: =Sheet1!$D$1 -> 9 | F34: =Sheet1!$E$1 -> 0
C35: Pending with RSG | E35: =Sheet1!$D$2 -> 22 | F35: =Sheet1!$E$2 -> 2991535.6
C36: Pending with RSG/FFC | E36: =Sheet1!$D$3 -> 4 | F36: =Sheet1!$E$3 -> 6684748.2
C37: Approved & Awaiting DVO | E37: =Sheet1!$D$4 -> 18 | F37: =Sheet1!$E$4 -> -23074.749
C38: DVO RR Issued | E38: =Sheet1!$D$5 -> 8 | F38: =Sheet1!$E$5 -> -362299.97
C39: Total Submitted VO | E39: =Sheet1!D7 -> 74 | F39: =Sheet1!E7 -> 25035632
B42: VANGUARD | C42: Commercial Summary · Internal use only | J42: ="REF: "&'Payment Register'!A46&" · COMMERCIAL TEAM FFC · ALL VALUES IN SAR" -> REF: IPA 28 · COMMERCIAL TEAM FFC · ALL VALUES IN SAR

Sheet Payment Register
A1: PAYMENT REGISTER-HW2C05
E2: =D4-D12 -> -4545500.3 | H2: `
A3: PROJECT DETAILS | C3: Summary of IPA's (without VAT) | G3: SUMMARY OF ADVANCE PAYMENT RECOVERY IPA
A4: Project: | B4: R06-HW2C05-5020 | C4: Original Contract Value | D4: 2.1750156e+08 | G4: Advance Payment | H4: =D17+D18 -> 65250467 | I4: 0.3209
A5: Contractor: | B5: First Fix | C5: Revised Contract Value | D5: =D4+Sheet1!E6+Sheet1!E5+Sheet1!E4 -> 2.328609e+08 | G5: Deducted till Date | H5: =-E51 -> 65250467 | I5: =H5/H4 -> 1
A6: Contract Date: | B6: 45189 | G6: Balance | H6: =H4-H5 -> 0.030560583 | I6: =H6/H4 -> 4.6835807e-10 | S6: .
C7: Under Review | D7: =SUMIF($Q$19:$Q$204,C7,$D$19:$D$204) -> 2696379.6 | E7: =D7/D5 -> 0.011579357
C8: Submitted on ACONEX | D8: =SUMIF($Q$19:$Q$204,C8,$D$19:$D$204) -> 0 | E8: =D8/D5 -> 0 | G8: SUMMARY OF RETENTION IPA
C9: Approved via Acconex | D9: =SUMIF($Q$19:$Q$204,C9,$D$19:$D$204) -> 3238453.1 | E9: =D9/D5 -> 0.013907242 | G9: Total Retention | H9: =D5*0.05 -> 11643045 | I9: 0.05
C10: Received | D10: =SUMIF($Q$19:$Q$204,C10,$D$19:$D$204) -> 2.188086e+08 | E10: =D10/D5 -> 0.93965367 | G10: Deducted till Date | H10: =-G51 -> 11102353 | I10: =H10/H9 -> 0.95356091
G11: Balance | H11: =H9-H10 -> 540692.4 | I11: =H11/H9 -> 0.046439088
C12: Total Work Done | D12: =D51 -> 2.2204706e+08 | E12: =D12/D5 -> 0.95356091
C13: Balance Work Done | D13: =D5-D12 -> 10813848 | E13: =D13/D5 -> 0.046439086
A15: No. | B15: Claim for Month / Invoice | D15: Gross Certified (Work executed) Amount | E15: Advance Payment Recovery | F15: Back Charge | G15: Less Retention (10%) | H15: VAT Recovery for Advance Payment | I15: VAT 15% | J15: Net Payment Certified | K15: Payment Recieved From Client | L15: Balance Due | M15: Submitted Date (FFC to TRSDC 1) | N15: Tax invoice sumbitted | O15: Due Date | P15: Payment Status | Q15: Status | R15: Payment Collected Date | S15: Remarks
S16: FFC Live Action | T16: RSG Live Action
A17: AP01 | B17: Adv Payment Invoice | D17: =D4*0.2 -> 43500311 | I17: =D17*0.15 -> 6525046.7 | J17: =SUM(D17:G17) -> 43500311 | K17: =J17 -> 43500311 | L17: =IF(OR($Q17="Approved via Acconex",$Q17="Approved via Mail"),J17,"") | M17: 45253 | N17: 45028 | P17: =IF(ISBLANK(N17),"",IF(Q17="Received","Paid",IF((TODAY()-N17)<21,"Due","Over Due")&" by "&TEXT((TODAY()-N17)-21,0)&" Days")) -> Paid | Q17: Received | S17: {=IFERROR(_xlfn.CHOOSECOLS(_xlfn._xlws.FILTER($X$17:$Z$21,$X$17:$X$21=Q17),2,3),"")} -> Transaction Received | T17: Transaction Placed | X17: Received | Y17: Transaction Received | Z17: Transaction Placed
A18: AP02 | B18: Adv Payment Invoice 2 | D18: 21750156 | I18: =D18*0.15 -> 3262523.3 | J18: =SUM(D18:G18) -> 21750156 | K18: =IF(Q18="Received",J18,"") -> 21750156 | L18: =IF(OR($Q18="Approved via Acconex",$Q18="Approved via Mail"),J18,"") | M18: 45616 | N18: 45618 | P18: =IF(ISBLANK(N18),"",IF(Q18="Received","Paid",IF((TODAY()-N18)<21,"Due","Over Due")&" by "&TEXT((TODAY()-N18)-21,0)&" Days")) -> Paid | Q18: Received | S18: {=IFERROR(_xlfn.CHOOSECOLS(_xlfn._xlws.FILTER($X$17:$Z$21,$X$17:$X$21=Q18),2,3),"")} -> Transaction Received | T18: Transaction Placed
A19: IPA 1 | B19: Sept 20th 2023 – Dec 25th 2023 | D19: 2571831.8 | E19: =-D19*0.2 -> -514366.36 | G19: =-D19*0.1 -> -257183.18 | H19: =E19*0.15 -> -77154.954 | I19: =D19*0.15 -> 385774.77 | J19: =SUM(D19:I19) -> 2108902.1 | K19: =IF($Q19="Received",J19,"") -> 2108902.1 | L19: =IF(OR($Q19="Approved via Acconex",$Q19="Approved via Mail"),J19,"") | M19: 45274 | N19: 45313 | P19: =IF(ISBLANK(N19),"",IF(Q19="Received","Paid",IF((TODAY()-N19)<21,"Due","Over Due")&" by "&TEXT((TODAY()-N19)-21,0)&" Days")) -> Paid | Q19: Received | S19: {=IFERROR(_xlfn.CHOOSECOLS(_xlfn._xlws.FILTER($X$17:$Z$21,$X$17:$X$21=Q19),2,3),"")} -> Transaction Received | T19: Transaction Placed | U19: =D19 -> 2571831.8 | X19: Approved via Acconex | Y19: Submitted Tax Invoice via Acconex Waiting For the Transaction | Z19: To place the payment | BO19: `
A20: IPA 2 | B20: Dec 25th 2023 – Jan 25th 2024 | D20: 1727779.5 | E20: =-D20*0.2 -> -345555.9 | G20: =-D20*0.1 -> -172777.95 | H20: =E20*0.15 -> -51833.384 | I20: =D20*0.15 -> 259166.92 | J20: =SUM(D20:I20) -> 1416779.2 | K20: =IF(Q20="Received",J20,"") -> 1416779.2 | L20: =IF(OR($Q20="Approved via Acconex",$Q20="Approved via Mail"),J20,"") | M20: 45321 | N20: 45377 | P20: =IF(ISBLANK(N20),"",IF(Q20="Received","Paid",IF((TODAY()-N20)<21,"Due","Over Due")&" by "&TEXT((TODAY()-N20)-21,0)&" Days")) -> Paid | Q20: Received | R20: 15/04/2024 | S20: {=IFERROR(_xlfn.CHOOSECOLS(_xlfn._xlws.FILTER($X$17:$Z$21,$X$17:$X$21=Q20),2,3),"")} -> Transaction Received | T20: Transaction Placed | U20: =D20+U19 -> 4299611.3 | X20: Submitted on ACONEX | Y20: Submitted Via acconex Waiting For payment Certificate | Z20: To send the Payment Certifcate
A21: IPA 3 | B21: Jan 25th 2024 – Feb 25th 2024 | D21: 1363441.9 | E21: =-D21*0.2 -> -272688.38 | G21: =-D21*0.1 -> -136344.19 | H21: =E21*0.15 -> -40903.257 | I21: =D21*0.15 -> 204516.28 | J21: =SUM(D21:I21) -> 1118022.3 | K21: =IF(Q21="Received",J21,"") -> 1118022.3 | L21: =IF(OR($Q21="Approved via Acconex",$Q21="Approved via Mail"),J21,"") | M21: 45404 | N21: 45630 | P21: =IF(ISBLANK(N21),"",IF(Q21="Received","Paid",IF((TODAY()-N21)<21,"Due","Over Due")&" by "&TEXT((TODAY()-N21)-21,0)&" Days")) -> Paid | Q21: Received | R21: 23/04/2024 | S21: {=IFERROR(_xlfn.CHOOSECOLS(_xlfn._xlws.FILTER($X$17:$Z$21,$X$17:$X$21=Q21),2,3),"")} -> Transaction Received | T21: Transaction Placed | U21: =D21+U20 -> 5663053.2 | X21: Under Review | Y21: Sent officially via mail/ Waiting for the Redsea assesment to Submit officially on Acconex | Z21: Under Assesment
A22: IPA 4 | B22: Feb 25th 2024 – Mar 25th 2024 | D22: 963176.5 | E22: =-D22*0.2 -> -192635.3 | G22: =-D22*0.1 -> -96317.65 | H22: =E22*0.15 -> -28895.295 | I22: =D22*0.15 -> 144476.48 | J22: =SUM(D22:I22) -> 789804.73 | K22: =IF(Q22="Received",J22,"") -> 789804.73 | L22: =IF(OR($Q22="Approved via Acconex",$Q22="Approved via Mail"),J22,"") | M22: 45427 | N22: 45425 | P22: =IF(ISBLANK(N22),"",IF(Q22="Received","Paid",IF((TODAY()-N22)<21,"Due","Over Due")&" by "&TEXT((TODAY()-N22)-21,0)&" Days")) -> Paid | Q22: Received | R22: 45571 | S22: {=IFERROR(_xlfn.CHOOSECOLS(_xlfn._xlws.FILTER($X$17:$Z$21,$X$17:$X$21=Q22),2,3),"")} -> Transaction Received | T22: Transaction Placed | U22: =D22+U21 -> 6626229.7
A23: IPA 5 | B23: Mar 25th 2024 – Apr 25th 2024 | D23: 6730484.9 | E23: =-D23*0.2 -> -1346097 | G23: =-D23*0.1 -> -673048.49 | H23: =E23*0.15 -> -201914.55 | I23: =D23*0.15 -> 1009572.7 | J23: =SUM(D23:I23) -> 5518997.7 | K23: =IF(Q23="Received",J23,"") -> 5518997.7 | L23: =IF(OR($Q23="Approved via Acconex",$Q23="Approved via Mail"),J23,"") | M23: 45440 | N23: 45440 | P23: =IF(ISBLANK(N23),"",IF(Q23="Received","Paid",IF((TODAY()-N23)<21,"Due","Over Due")&" by "&TEXT((TODAY()-N23)-21,0)&" Days")) -> Paid | Q23: Received | R23: 14/06/2024 | S23: {=IFERROR(_xlfn.CHOOSECOLS(_xlfn._xlws.FILTER($X$17:$Z$21,$X$17:$X$21=Q23),2,3),"")} -> Transaction Received | T23: Transaction Placed | U23: =D23+U22 -> 13356715
A24: IPA 6 | B24: Apr 25th 2024 – May 25th 2024 | D24: 3008114.1 | E24: =-D24*0.2 -> -601622.82 | G24: =-D24*0.1 -> -300811.41 | H24: =E24*0.15 -> -90243.423 | I24: =D24*0.15 -> 451217.11 | J24: =SUM(D24:I24) -> 2466653.6 | K24: =IF(Q24="Received",J24,"") -> 2466653.6 | L24: =IF(OR($Q24="Approved via Acconex",$Q24="Approved via Mail"),J24,"") | M24: 45411 | N24: 45470 | P24: =IF(ISBLANK(N24),"",IF(Q24="Received","Paid",IF((TODAY()-N24)<21,"Due","Over Due")&" by "&TEXT((TODAY()-N24)-21,0)&" Days")) -> Paid | Q24: Received | R24: 17/07/2024 | S24: {=IFERROR(_xlfn.CHOOSECOLS(_xlfn._xlws.FILTER($X$17:$Z$21,$X$17:$X$21=Q24),2,3),"")} -> Transaction Received | T24: Transaction Placed | U24: =D24+U23 -> 16364829
A25: IPA 7 | B25: May 25th 2024 – Jun 25th 2024 | D25: 3972034.7 | E25: =-D25*0.2 -> -794406.94 | G25: =-D25*0.1 -> -397203.47 | H25: =E25*0.15 -> -119161.04 | I25: =D25*0.15 -> 595805.2 | J25: =SUM(D25:I25) -> 3257068.4 | K25: =IF(Q25="Received",J25,"") -> 3257068.4 | L25: =IF(OR($Q25="Approved via Acconex",$Q25="Approved via Mail"),J25,"") | M25: 45469 | N25: 45501 | P25: =IF(ISBLANK(N25),"",IF(Q25="Received","Paid",IF((TODAY()-N25)<21,"Due","Over Due")&" by "&TEXT((TODAY()-N25)-21,0)&" Days")) -> Paid | Q25: Received | R25: 13/08/2024 | S25: {=IFERROR(_xlfn.CHOOSECOLS(_xlfn._xlws.FILTER($X$17:$Z$21,$X$17:$X$21=Q25),2,3),"")} -> Transaction Received | T25: Transaction Placed | U25: =D25+U24 -> 20336863
A26: IPA 8 | B26: Jun 25th 2024 – Jul 25th 2024 | D26: 5556560.4 | E26: =-D26*0.2 -> -1111312.1 | G26: =-D26*0.1 -> -555656.04 | H26: =E26*0.15 -> -166696.81 | I26: =D26*0.15 -> 833484.06 | J26: =SUM(D26:I26) -> 4556379.5 | K26: =IF(Q26="Received",J26,"") -> 4556379.5 | L26: =IF(OR($Q26="Approved via Acconex",$Q26="Approved via Mail"),J26,"") | M26: 45523 | N26: 45478 | P26: =IF(ISBLANK(N26),"",IF(Q26="Received","Paid",IF((TODAY()-N26)<21,"Due","Over Due")&" by "&TEXT((TODAY()-N26)-21,0)&" Days")) -> Paid | Q26: Received | S26: {=IFERROR(_xlfn.CHOOSECOLS(_xlfn._xlws.FILTER($X$17:$Z$21,$X$17:$X$21=Q26),2,3),"")} -> Transaction Received | T26: Transaction Placed | U26: =D26+U25 -> 25893424
A27: IPA 9 | B27: Jul 25th 2024 – Aug 25th 2024 | D27: 6512584.8 | E27: =-D27*0.2 -> -1302517 | G27: =-D27*0.1 -> -651258.48 | H27: =E27*0.15 -> -195377.54 | I27: =D27*0.15 -> 976887.72 | J27: =SUM(D27:I27) -> 5340319.6 | K27: =IF(Q27="Received",J27,"") -> 5340319.6 | L27: =IF(OR($Q27="Approved via Acconex",$Q27="Approved via Mail"),J27,"") | M27: 45535 | N27: 45571 | P27: =IF(ISBLANK(N27),"",IF(Q27="Received","Paid",IF((TODAY()-N27)<21,"Due","Over Due")&" by "&TEXT((TODAY()-N27)-21,0)&" Days")) -> Paid | Q27: Received | R27: 45588 | S27: {=IFERROR(_xlfn.CHOOSECOLS(_xlfn._xlws.FILTER($X$17:$Z$21,$X$17:$X$21=Q27),2,3),"")} -> Transaction Received | T27: Transaction Placed | U27: =D27+U26 -> 32406009
A28: IPA 10 | B28: Aug 25th 2024 – Sep 25th 2024 | D28: 5212335 | E28: =-D28*0.2 -> -1042467 | G28: =-D28*0.1 -> -521233.5 | H28: =E28*0.15 -> -156370.05 | I28: =D28*0.15 -> 781850.25 | J28: =SUM(D28:I28) -> 4274114.7 | K28: =IF(Q28="Received",J28,"") -> 4274114.7 | L28: =IF(OR($Q28="Approved via Acconex",$Q28="Approved via Mail"),J28,"") | M28: 45567 | N28: 45586 | P28: =IF(ISBLANK(N28),"",IF(Q28="Received","Paid",IF((TODAY()-N28)<21,"Due","Over Due")&" by "&TEXT((TODAY()-N28)-21,0)&" Days")) -> Paid | Q28: Received | S28: {=IFERROR(_xlfn.CHOOSECOLS(_xlfn._xlws.FILTER($X$17:$Z$21,$X$17:$X$21=Q28),2,3),"")} -> Transaction Received | T28: Transaction Placed | U28: =D28+U27 -> 37618344
A29: IPA 11 | B29: Sep 25th 2024 – Oct 25th 2024 | D29: 11178597 | E29: =-D29*32.09% -> -3587211.9 | G29: =-D29*0.1 -> -1117859.7 | H29: =E29*0.15 -> -538081.78 | I29: =D29*0.15 -> 1676789.6 | J29: =SUM(D29:I29) -> 7612233.5 | K29: =IF(Q29="Received",J29,"") -> 7612233.5 | L29: =IF(OR($Q29="Approved via Acconex",$Q29="Approved via Mail"),J29,"") | M29: 45619 | N29: 45639 | P29: =IF(ISBLANK(N29),"",IF(Q29="Received","Paid",IF((TODAY()-N29)<21,"Due","Over Due")&" by "&TEXT((TODAY()-N29)-21,0)&" Days")) -> Paid | Q29: Received | S29: {=IFERROR(_xlfn.CHOOSECOLS(_xlfn._xlws.FILTER($X$17:$Z$21,$X$17:$X$21=Q29),2,3),"")} -> Transaction Received | T29: Transaction Placed | U29: =D29+U28 -> 48796941
A30: IPA 12 | B30: Oct 25th 2024 – Nov 25th 2024 | D30: 5338593.9 | E30: =-D30*32.09% -> -1713154.8 | G30: =-D30*0.1 -> -533859.39 | H30: =E30*0.15 -> -256973.22 | I30: =D30*0.15 -> 800789.08 | J30: =SUM(D30:I30) -> 3635395.6 | K30: =IF(Q30="Received",J30,"") -> 3635395.6 | L30: =IF(OR($Q30="Approved via Acconex",$Q30="Approved via Mail"),J30,"") | M30: 45634 | N30: 45655 | P30: =IF(ISBLANK(N30),"",IF(Q30="Received","Paid",IF((TODAY()-N30)<21,"Due","Over Due")&" by "&TEXT((TODAY()-N30)-21,0)&" Days")) -> Paid | Q30: Received | S30: {=IFERROR(_xlfn.CHOOSECOLS(_xlfn._xlws.FILTER($X$17:$Z$21,$X$17:$X$21=Q30),2,3),"")} -> Transaction Received | T30: Transaction Placed | U30: =D30+U29 -> 54135535
A31: IPA 13 | B31: Nov 25th 2024 – Dec 25th 2024 | D31: 10523911 | E31: =-D31*32.09% -> -3377123.1 | G31: =-D31*0.1 -> -1052391.1 | H31: =E31*0.15 -> -506568.46 | I31: =D31*0.15 -> 1578586.7 | J31: =SUM(D31:I31) -> 7166415.1 | K31: =IF(Q31="Received",J31,"") -> 7166415.1 | L31: =IF(OR($Q31="Approved via Acconex",$Q31="Approved via Mail"),J31,"") | M31: 45676 | N31: 45690 | P31: =IF(ISBLANK(N31),"",IF(Q31="Received","Paid",IF((TODAY()-N31)<21,"Due","Over Due")&" by "&TEXT((TODAY()-N31)-21,0)&" Days")) -> Paid | Q31: Received | S31: {=IFERROR(_xlfn.CHOOSECOLS(_xlfn._xlws.FILTER($X$17:$Z$21,$X$17:$X$21=Q31),2,3),"")} -> Transaction Received | T31: Transaction Placed | U31: =D31+U30 -> 64659446
A32: IPA 14 | B32: Dec 25th 2024 – Jan 25th 2025 | D32: 14789523 | E32: =-D32*32.09% -> -4745957.8 | G32: =-D32*0.1 -> -1478952.3 | H32: =E32*0.15 -> -711893.67 | I32: =D32*0.15 -> 2218428.4 | J32: =SUM(D32:I32) -> 10071147 | K32: =IF(Q32="Received",J32,"") -> 10071147 | L32: =IF(OR($Q32="Approved via Acconex",$Q32="Approved via Mail"),J32,"") | M32: 45701 | N32: 45718 | P32: =IF(ISBLANK(N32),"",IF(Q32="Received","Paid",IF((TODAY()-N32)<21,"Due","Over Due")&" by "&TEXT((TODAY()-N32)-21,0)&" Days")) -> Paid | Q32: Received | S32: {=IFERROR(_xlfn.CHOOSECOLS(_xlfn._xlws.FILTER($X$17:$Z$21,$X$17:$X$21=Q32),2,3),"")} -> Transaction Received | T32: Transaction Placed | U32: =D32+U31 -> 79448968
A33: IPA 15 | B33: Jan 25th 2025 – Feb 25th 2025 | D33: 14091615 | E33: =-D33*32.09% -> -4521999.2 | G33: =-D33*0.1 -> -1409161.5 | H33: =E33*0.15 -> -678299.88 | I33: =D33*0.15 -> 2113742.2 | J33: =SUM(D33:I33) -> 9595896.5 | K33: =IF(Q33="Received",J33,"") -> 9595896.5 | L33: =IF(OR($Q33="Approved via Acconex",$Q33="Approved via Mail"),J33,"") | M33: 45734 | N33: 45743 | P33: =IF(ISBLANK(N33),"",IF(Q33="Received","Paid",IF((TODAY()-N33)<21,"Due","Over Due")&" by "&TEXT((TODAY()-N33)-21,0)&" Days")) -> Paid | Q33: Received | S33: {=IFERROR(_xlfn.CHOOSECOLS(_xlfn._xlws.FILTER($X$17:$Z$21,$X$17:$X$21=Q33),2,3),"")} -> Transaction Received | T33: Transaction Placed | U33: =D33+U32 -> 93540583
A34: IPA 16 | B34: Feb 25th 2025 – Mar 25th 2025 | D34: 5147125.9 | E34: =-D34*32.09% -> -1651712.7 | G34: =-D34*0.1 -> -514712.59 | H34: =E34*0.15 -> -247756.91 | I34: =D34*0.15 -> 772068.89 | J34: =SUM(D34:I34) -> 3505012.6 | K34: =IF(Q34="Received",J34,"") -> 3505012.6 | L34: =IF(OR($Q34="Approved via Acconex",$Q34="Approved via Mail"),J34,"") | M34: 45770 | N34: 45784 | P34: =IF(ISBLANK(N34),"",IF(Q34="Received","Paid",IF((TODAY()-N34)<21,"Due","Over Due")&" by "&TEXT((TODAY()-N34)-21,0)&" Days")) -> Paid | Q34: Received | S34: {=IFERROR(_xlfn.CHOOSECOLS(_xlfn._xlws.FILTER($X$17:$Z$21,$X$17:$X$21=Q34),2,3),"")} -> Transaction Received | T34: Transaction Placed | U34: =D34+U33 -> 98687709
A35: IPA 17 | B35: Mar 25th 2025 – Apr 25th 2025 | D35: 14619844 | E35: =-D35*32.09% -> -4691507.9 | G35: =-D35*0.1 -> -1461984.4 | H35: =E35*0.15 -> -703726.18 | I35: =D35*0.15 -> 2192976.6 | J35: =SUM(D35:I35) -> 9955601.9 | K35: =IF(Q35="Received",J35,"") -> 9955601.9 | L35: =IF(OR($Q35="Approved via Acconex",$Q35="Approved via Mail"),J35,"") | M35: 45790 | N35: 45801 | P35: =IF(ISBLANK(N35),"",IF(Q35="Received","Paid",IF((TODAY()-N35)<21,"Due","Over Due")&" by "&TEXT((TODAY()-N35)-21,0)&" Days")) -> Paid | Q35: Received | S35: {=IFERROR(_xlfn.CHOOSECOLS(_xlfn._xlws.FILTER($X$17:$Z$21,$X$17:$X$21=Q35),2,3),"")} -> Transaction Received | T35: Transaction Placed | U35: =D35+U34 -> 1.1330755e+08
A36: IPA 18 | B36: Apr 25th 2025 – May 25th 2025 | D36: 13904094 | E36: =-D36*32.09% -> -4461823.7 | G36: =-D36*0.1 -> -1390409.4 | H36: =E36*0.15 -> -669273.55 | I36: =D36*0.15 -> 2085614 | J36: =SUM(D36:I36) -> 9468201.1 | K36: =IF(Q36="Received",J36,"") -> 9468201.1 | L36: =IF(OR($Q36="Approved via Acconex",$Q36="Approved via Mail"),J36,"") | M36: 45826 | N36: 45836 | P36: =IF(ISBLANK(N36),"",IF(Q36="Received","Paid",IF((TODAY()-N36)<21,"Due","Over Due")&" For "&TEXT((TODAY()-N36)-21,0)&" Days")) -> Paid | Q36: Received | S36: {=IFERROR(_xlfn.CHOOSECOLS(_xlfn._xlws.FILTER($X$17:$Z$21,$X$17:$X$21=Q36),2,3),"")} -> Transaction Received | T36: Transaction Placed | U36: =D36+U35 -> 1.2721165e+08
A37: IPA 19 | B37: May 25th 2025 – Jun 25th 2025 | D37: 9497761.4 | E37: =-D37*32.09% -> -3047831.6 | G37: =-D37*0.1 -> -949776.14 | H37: =E37*0.15 -> -457174.74 | I37: =D37*0.15 -> 1424664.2 | J37: =SUM(D37:I37) -> 6467643.1 | K37: =IF(Q37="Received",J37,"") -> 6467643.1 | L37: =IF(OR($Q37="Approved via Acconex",$Q37="Approved via Mail"),J37,"") | M37: 45824 | N37: 45867 | P37: =IF(ISBLANK(N37),"",IF(Q37="Received","Paid",IF((TODAY()-N37)<21,"Due","Over Due")&" For "&TEXT((TODAY()-N37)-21,0)&" Days")) -> Paid | Q37: Received | S37: {=IFERROR(_xlfn.CHOOSECOLS(_xlfn._xlws.FILTER($X$17:$Z$21,$X$17:$X$21=Q37),2,3),"")} -> Transaction Received | T37: Transaction Placed | U37: =D37+U36 -> 1.3670941e+08
A38: IPA 20 | B38: Jun 25th 2025 – Jul 25th 2025 | D38: 6813139.3 | E38: =-D38*32.09% -> -2186336.4 | G38: =-D38*0.1 -> -681313.93 | H38: =E38*0.15 -> -327950.46 | I38: =D38*0.15 -> 1021970.9 | J38: =SUM(D38:I38) -> 4639509.4 | K38: =IF(Q38="Received",J38,"") -> 4639509.4 | L38: =IF(OR($Q38="Approved via Acconex",$Q38="Approved via Mail"),J38,"") | M38: 45904 | N38: 45916 | P38: =IF(ISBLANK(N38),"",IF(Q38="Received","Paid",IF((TODAY()-N38)<21,"Due","Over Due")&" For "&TEXT((TODAY()-N38)-21,0)&" Days")) -> Paid | Q38: Received | S38: {=IFERROR(_xlfn.CHOOSECOLS(_xlfn._xlws.FILTER($X$17:$Z$21,$X$17:$X$21=Q38),2,3),"")} -> Transaction Received | T38: Transaction Placed | U38: =D38+U37 -> 1.4352255e+08
A39: IPA 21 | B39: Jul 25th 2025 – Aug 25th 2025 | D39: 5324464.1 | E39: =-D39*32.09% -> -1708620.5 | G39: 6909904.2 | H39: =E39*0.15 -> -256293.08 | I39: =D39*0.15 -> 798669.62 | J39: =SUM(D39:I39) -> 11068124 | K39: =IF(Q39="Received",J39,"") -> 11068124 | L39: =IF(OR($Q39="Approved via Acconex",$Q39="Approved via Mail"),J39,"") | M39: 45915 | N39: 45946 | P39: =IF(ISBLANK(N39),"",IF(Q39="Received","Paid",IF((TODAY()-N39)<21,"Due","Over Due")&" In "&TEXT((TODAY()-N39)-21,0)&" Days")) -> Paid | Q39: Received | S39: {=IFERROR(_xlfn.CHOOSECOLS(_xlfn._xlws.FILTER($X$17:$Z$21,$X$17:$X$21=Q39),2,3),"")} -> Transaction Received | T39: Transaction Placed | U39: =D39+U38 -> 1.4884701e+08
A40: IPA 22 | B40: Aug 25th 2025 – Sep 25th 2025 | D40: 6418102.4 | E40: =-D40*32.09% -> -2059569 | G40: =-D40*5% -> -320905.12 | H40: =E40*0.15 -> -308935.36 | I40: =D40*0.15 -> 962715.35 | J40: =SUM(D40:I40) -> 4691408.2 | K40: =IF(Q40="Received",J40,"") -> 4691408.2 | L40: =IF(OR($Q40="Approved via Acconex",$Q40="Approved via Mail"),J40,"") | M40: 45949 | N40: 45963 | O40: =N40+21 -> 45984 | P40: =IF(ISBLANK(N40),"",IF(Q40="Received","Paid",IF((TODAY()-N40)<21,"Due","Over Due")&" In "&TEXT((TODAY()-N40)-21,0)&" Days")) -> Paid | Q40: Received | S40: {=IFERROR(_xlfn.CHOOSECOLS(_xlfn._xlws.FILTER($X$17:$Z$21,$X$17:$X$21=Q40),2,3),"")} -> Transaction Received | T40: Transaction Placed | U40: =D40+U39 -> 1.5526511e+08
A41: IPA 23 | B41: Sep 25th 2025 – Oct 25th 2025 | D41: 18005054 | E41: =-D41*32.09% -> -5777821.8 | G41: =-D41*5% -> -900252.7 | H41: =E41*0.15 -> -866673.28 | I41: =D41*0.15 -> 2700758.1 | J41: =SUM(D41:I41) -> 13161064 | K41: =IF(Q41="Received",J41,"") -> 13161064 | L41: =IF(OR($Q41="Approved via Acconex",$Q41="Approved via Mail"),J41,"") | M41: 45972 | N41: 45988 | P41: =IF(ISBLANK(N41),"",IF(Q41="Received","Paid",IF((TODAY()-N41)<21,"Due","Over Due")&" In "&TEXT((TODAY()-N41)-21,0)&" Days")) -> Paid | Q41: Received | S41: {=IFERROR(_xlfn.CHOOSECOLS(_xlfn._xlws.FILTER($X$17:$Z$21,$X$17:$X$21=Q41),2,3),"")} -> Transaction Received | T41: Transaction Placed | U41: =D41+U40 -> 1.7327017e+08
...

Sheet VO LOG (2)
B1: =TODAY() -> 46232
L3: Revised Contract | N3: =217501556.115897+Sheet1!E5+Sheet1!E4+Sheet1!E6 -> 2.328609e+08
F4: REVISED CONTRACT VALUE
X5: =G4-N19 -> -519455.46
Y6: 2.3143716e+08
Y7: =Y6-X5 -> 2.3195661e+08
B10: S.No | C10: VO Number | D10: VO Date In Accinex | E10: DVO Reference | F10: Subject | G10: Submission | H10: Submission Type (RFP/VAR/Gen CORR) | I10: Submission ref# | J10: Response Email Ref | K10: Assesment | L10: Cost Proposal Value | M10: RSG Assesment | N10: To Summary | O10: Status | P10: VOR | Q10: DVO Ref | R10: R Remarks | S10: RSG Remarks | U10: Raw Link | V10: Submission Link | X10: Status | Z10: Done by
B11: 1 | C11: =LEFT(IFERROR("VO-"&_xlfn.TEXTAFTER(P11,"-00"),""),5) -> VO-02 | D11: 45502 | E11: DVO-CM-0002 | F11: ETS Room Standby Equipment Removal | G11: 45510 | H11: VO | I11: FFC06HW2-GENCORR-000182 | J11: FFC06HW2-GENCORR-000182 | N11: -436711.91 | O11: DVO Issued | P11: R06-HW2C05-TRS-VOR-CM-0002 | Q11: R06-HW2C05-TRS-DVO-CM-0002 | R11: Closed Out | S11: Closed / Agreed | U11: =HYPERLINK("https://ksa1.aconex.com/MiniURL?type=MAILSEARCH&mailbox=5&pid=1342178882&cid=1377669720","Open in Aconex") -> Open in Aconex | V11: =HYPERLINK("https://ksa1.aconex.com/MiniURL?type=MAILSEARCH&mailbox=5&pid=1342178882&cid=1378119163","View Submission") -> View Submission | Z11: finished
B12: =B11+1 -> 2 | C12: =LEFT(IFERROR("VO-"&_xlfn.TEXTAFTER(P12,"-00"),""),5) -> VO-01 | D12: 45424 | E12: DVO-CM-0001 | F12: Change in Generator from Biofuel to Standard Tier 1 Diesel | G12: 45452 | H12: VO | I12: TRS06HW2-GENCORR-000846 | J12: TRS06HW2-GENCORR-000846 | N12: -1050000 | O12: DVO Issued | P12: R06-HW2C05-TRS-VOR-CM-0001 | Q12: R06-HW2C05-TRS-DVO-CM-0001 | R12: Closed Out | S12: Closed / Agreed | U12: =HYPERLINK("https://ksa1.aconex.com/MiniURL?type=MAILSEARCH&mailbox=5&pid=1342178882&cid=1374145720","Open in Aconex") -> Open in Aconex | V12: =HYPERLINK("https://ksa1.aconex.com/MiniURL?type=MAILSEARCH&mailbox=5&pid=1342178882&cid=1375381973","View Submission") -> View Submission | X12: DVO Issued | Z12: finished
B13: =B12+1 -> 3 | C13: =LEFT(IFERROR("VO-"&_xlfn.TEXTAFTER(P13,"-00"),""),5) -> VO-05 | D13: 45433 | E13: DVO-CM-0005 | F13: Issued for Construction (IFC N1) Documents Buildings | G13: 45542 | H13: VO | I13: FFC06HW2-GENCORR-000187 | J13: FFC06HW2-GENCORR-000190 | N13: 1100693.1 | O13: DVO Issued | P13: R06-HW2C05-TRS-DVO-CM-0005 | Q13: R06-HW2C05-TRS-DVO-CM-0005 | R13: Closed Out | S13: Closed / Agreed | U13: =HYPERLINK("https://ksa1.aconex.com/MiniURL?type=MAILSEARCH&mailbox=5&pid=1342178882&cid=1374600277","Open in Aconex") -> Open in Aconex | V13: =HYPERLINK("https://ksa1.aconex.com/MiniURL?type=MAILSEARCH&mailbox=5&pid=1342178882&cid=1379618554","View Submission") -> View Submission | X13: DVO RR Issued | Z13: Roomy
B14: =B13+1 -> 4 | C14: =LEFT(IFERROR("VO-"&_xlfn.TEXTAFTER(P14,"-00"),""),5) -> VO-05 | D14: 45433 | E14: DVO-CM-0005 | F14: Issued for Construction (IFC N1) Documents Infra | G14: 45538 | H14: VO | I14: FFC06HW2-GENCORR-000187 | J14: FFC06HW2-GENCORR-000187 | N14: 3001607.6 | O14: DVO Issued | P14: R06-HW2C05-TRS-VOR-CM-0005 | Q14: R06-HW2C05-TRS-DVO-CM-0005 | R14: Closed Out | S14: Closed / Agreed | U14: =HYPERLINK("https://ksa1.aconex.com/MiniURL?type=MAILSEARCH&mailbox=5&pid=1342178882&cid=1374600277","Open in Aconex") -> Open in Aconex | V14: =HYPERLINK("https://ksa1.aconex.com/MiniURL?type=MAILSEARCH&mailbox=5&pid=1342178882&cid=1379618554","View Submission") -> View Submission | X14: Approved , Pending DVO | Z14: finished
B15: =B14+1 -> 5 | C15: =LEFT(IFERROR("VO-"&_xlfn.TEXTAFTER(P15,"-00"),""),5) -> VO-05 | D15: 45433 | E15: DVO-CM-0005 | F15: Issued for Construction (IFC N1) Documents Pool | G15: 45539 | H15: VO | I15: FFC06HW2-GENCORR-000187 | J15: FFC06HW2-GENCORR-000189 | N15: 558521.84 | O15: DVO Issued | P15: R06-HW2C05-TRS-VOR-CM-0005 | Q15: R06-HW2C05-TRS-DVO-CM-0005 | R15: Closed Out | S15: Closed / Agreed | U15: =HYPERLINK("https://ksa1.aconex.com/MiniURL?type=MAILSEARCH&mailbox=5&pid=1342178882&cid=1374600277","Open in Aconex") -> Open in Aconex | V15: =HYPERLINK("https://ksa1.aconex.com/MiniURL?type=MAILSEARCH&mailbox=5&pid=1342178882&cid=1379618554","View Submission") -> View Submission | X15: Pending with RSG | Z15: finished
B16: =B15+1 -> 6 | C16: =LEFT(IFERROR("VO-"&_xlfn.TEXTAFTER(P16,"-00"),""),5) -> VO-08 | D16: 45546 | E16: DVO-CM-0008 | F16: Changing ACCU Room to Storage Room in Asset 60 (HOH) | G16: 45552 | H16: VO | I16: FFC06HW2-GENCORR-000192 | J16: FFC06HW2-GENCORR-000192 | N16: 15581.88 | O16: DVO Issued | P16: R06-HW2C05-TRS-VOR-CM-0008 | Q16: R06-HW2C05-TRS-DVO-CM-0008 | R16: Closed Out | S16: Closed / Agreed | U16: =HYPERLINK("https://ksa1.aconex.com/MiniURL?type=MAILSEARCH&mailbox=5&pid=1342178882&cid=1380050516","Open in Aconex") -> Open in Aconex | V16: =HYPERLINK("https://ksa1.aconex.com/MiniURL?type=MAILSEARCH&mailbox=5&pid=1342178882&cid=1380366174","View Submission") -> View Submission | X16: Pending with RSG/FFC | Z16: finished
B17: =B16+1 -> 7 | C17: =LEFT(IFERROR("VO-"&_xlfn.TEXTAFTER(P17,"-00"),""),5) -> VO-07 | D17: 45589 | E17: DVO-CM-0007 | F17: Relocation of CCTV cameras (6 nr) to meet operational requirements | G17: 45661 | H17: VO | I17: FFC06HW2-GENCORR-000207 | J17: FFC06HW2-GENCORR-000207 | L17: -40876.88 | M17: 0 | N17: 0 | O17: DVO Issued | P17: R06-HW2C05-TRS-VOR-CM-0007 | Q17: R06-HW2C05-TRS-DVO-CM-0007 | R17: Closed Out | S17: Closed / Agreed | U17: =HYPERLINK("https://ksa1.aconex.com/MiniURL?type=MAILSEARCH&mailbox=5&pid=1342178882&cid=1382366478","Open in Aconex") -> Open in Aconex | V17: =HYPERLINK("https://ksa1.aconex.com/MiniURL?type=MAILSEARCH&mailbox=5&pid=1342178882&cid=1386223816","View Submission") -> View Submission | X17: Pending with FFC
B18: =B17+1 -> 8 | C18: =LEFT(IFERROR("VO-"&_xlfn.TEXTAFTER(P18,"-00"),""),5) -> VO-15 | D18: 45650 | E18: DVO-CM-0015 | F18: MEP Works inside Villas & Clusters Bathrooms and associated Interfaces | G18: 45704 | H18: VO | I18: FFC06HW2-GENCORR-000212 | J18: FFC06HW2-GENCORR-000261 | L18: 10699031 | N18: 10699031 | O18: DVO Issued | P18: R06-HW2C05-TRS-VOR-CM-0015 | Q18: R06-HW2C05-TRS-DVO-CM-0015 | R18: Closed Out | S18: Closed / Agreed | U18: =HYPERLINK("https://ksa1.aconex.com/MiniURL?type=MAILSEARCH&mailbox=5&pid=1342178882&cid=1385687757","Open in Aconex") -> Open in Aconex | V18: =HYPERLINK("https://ksa1.aconex.com/MiniURL?type=MAILSEARCH&mailbox=5&pid=1342178882&cid=1386447039","View Submission") -> View Submission | X18: Not Eligible | Z18: Roomy
B19: =B18+1 -> 9 | C19: =LEFT(IFERROR("VO-"&_xlfn.TEXTAFTER(P19,"-00"),""),5) -> VO-22 | D19: 45768 | E19: DVO-CM-0022 | F19: Sewage Network final Tie-in to PPP Manhole - Additional Lift Station | G19: 45796 | H19: VO | I19: FFC06HW2-GENCORR-000343 | J19: FFC06HW2-GENCORR-000368 | K19: 45873 | L19: 635771.67 | M19: 519455.46 | N19: 519455.46 | O19: DVO Issued | P19: R06-HW2C05-TRS-VOR-CM-0022 | Q19: R06-HW2C05-TRS-DVO-CM-0022 | R19: Closed Out | S19: Closed / Agreed | V19: =HYPERLINK("https://ksa1.aconex.com/MiniURL?type=MAILSEARCH&mailbox=5&pid=1342178882&cid=1392411012","View Submission") -> View Submission | Z19: Roomy
B20: =B19+1 -> 10 | C20: =LEFT(IFERROR("VO-"&_xlfn.TEXTAFTER(P20,"-00"),""),5) -> VO-25 | D20: 45847 | E20: DVO-CM-0025 | F20: Change from 13A single switch outlet to 13A twin switched socket outlet for the Minibar Fridge on HW2 Villas and Clusters | G20: 45853 | H20: VO | I20: FFC06HW2-GENCORR-000413 | J20: FFC06HW2-GENCORR-000413 | K20: 45858 | L20: 19944.67 | M20: 17343.19 | N20: 17343.19 | O20: DVO Issued | P20: R06-HW2C05-TRS-VOR-CM-0025 | Q20: R06-HW2C05-TRS-DVO-CM-0025 | R20: Closed Out | S20: Closed / Agreed | U20: =HYPERLINK("https://ksa1.aconex.com/MiniURL?type=MAILSEARCH&mailbox=5&pid=1342178882&cid=1396038682","Open in Aconex") -> Open in Aconex | V20: =HYPERLINK("https://ksa1.aconex.com/MiniURL?type=MAILSEARCH&mailbox=5&pid=1342178882&cid=1396374231","View Submission") -> View Submission | Z20: Aaqil
B21: =B20+1 -> 11 | C21: =LEFT(IFERROR("VO-"&_xlfn.TEXTAFTER(P21,"-00"),""),5) -> VO-04 | D21: 45442 | E21: DVO-CM-0004 | F21: Changing Backup Strategy to Equipment Serving ICT Rooms Instruction Reference | G21: 45692 | H21: VO | I21: FFC06HW2-GENCORR-000247 | J21: FFC06HW2-GENCORR-000247 | L21: -278670.94 | M21: -747365.98 | N21: -504221.15 | O21: DVO Issued | P21: R06-HW2C05-TRS-VOR-CM-0004 | Q21: R06-HW2C05-TRS-DVO-CM-0004 | R21: Closed Out | S21: Closed / Agreed | V21: =HYPERLINK("https://ksa1.aconex.com/MiniURL?type=MAILSEARCH&mailbox=5&pid=1342178882&cid=1387993288","View Submission") -> View Submission | Z21: Roomy
B22: =B21+1 -> 12 | C22: =LEFT(IFERROR("VO-"&_xlfn.TEXTAFTER(P22,"-00"),""),5) -> VO-20 | D22: 45843 | E22: DVO-CM-0020 | F22: Provision of Temporary Cooling to First In Place Assets | G22: 45857 | H22: VO | I22: FFC06HW2-GENCORR-000415 | J22: FFC06HW2-GENCORR-000415 | K22: 45892 | L22: 669692.26 | M22: 372927.79 | N22: 372927.79 | O22: DVO Issued | P22: R06-HW2C05-TRS-VOR-CM-0020 | Q22: R06-HW2C05-TRS-DVO-CM-0020 | R22: Closed Out | S22: Closed / Agreed | U22: =HYPERLINK("https://ksa1.aconex.com/MiniURL?type=MAILSEARCH&mailbox=5&pid=1342178882&cid=1395787836","Open in Aconex") -> Open in Aconex | V22: =HYPERLINK("https://ksa1.aconex.com/MiniURL?type=MAILSEARCH&mailbox=5&pid=1342178882&cid=1396610099","View Submission") -> View Submission | Z22: finished
B23: =B22+1 -> 13 | C23: =LEFT(IFERROR("VO-"&_xlfn.TEXTAFTER(P23,"-00"),""),5) -> VO-27 | D23: 45816 | E23: DVO-CM-0027 | F23: Omission of 13A twin socket outlets and Replace with combined MEP and ELV Faceplates | G23: 45858 | H23: VO | I23: FFC06HW2-GENCORR-000416 | J23: FFC06HW2-GENCORR-000416 | K23: 45874 | L23: 81841.95 | M23: 46879.801 | N23: 46879.8 | O23: DVO Issued | P23: R06-HW2C05-TRS-VOR-CM-0027 | Q23: R06-HW2C05-TRS-DVO-CM-0027 | R23: Closed Out | S23: Closed / Agreed | U23: =HYPERLINK("https://ksa1.aconex.com/MiniURL?type=MAILSEARCH&mailbox=5&pid=1342178882&cid=1394408468","Open in Aconex") -> Open in Aconex | V23: =HYPERLINK("https://ksa1.aconex.com/MiniURL?type=MAILSEARCH&mailbox=5&pid=1342178882&cid=1396622443","View Submission") -> View Submission | Z23: finished
B24: =B23+1 -> 14 | C24: =LEFT(IFERROR("VO-"&_xlfn.TEXTAFTER(P24,"-00"),""),5) -> VO-26 | D24: 45829 | E24: DVO-CM-0026 | F24: Change in Bollard Lighting Fixtures luminaire ref. LA1 | G24: 45832 | H24: VO | I24: FFC06HW2-GENCORR-000406 | J24: FFC06HW2-GENCORR-000406 | K24: 45861 | L24: 318771.22 | M24: -95869.692 | N24: -95869.692 | O24: DVO Issued | P24: R06-HW2C05-TRS-VOR-CM-0026 | Q24: R06-HW2C05-TRS-VOR-DVO-0026 | R24: Closed Out | S24: Closed / Agreed | U24: =HYPERLINK("https://ksa1.aconex.com/MiniURL?type=MAILSEARCH&mailbox=5&pid=1342178882&cid=1394972529","Open in Aconex") -> Open in Aconex | V24: =HYPERLINK("https://ksa1.aconex.com/MiniURL?type=MAILSEARCH&mailbox=5&pid=1342178882&cid=1395185431","View Submission") -> View Submission | Z24: finished
B25: =B24+1 -> 15 | C25: =LEFT(IFERROR("VO-"&_xlfn.TEXTAFTER(P25,"-00"),""),5) -> VO-12 | D25: 45606 | E25: DVO-CM-0012 | F25: HW2 Family Pool Enlargement | G25: 45930 | H25: VO | I25: FFC06HW2-GENCORR-000244 | J25: FFC06HW2-GENCORR-000244 | K25: 45936 | L25: 1166471.2 | M25: 912623.79 | N25: 912623.79 | O25: DVO Issued | P25: R06-HW2C05-TRS-VOR-CM-0012 | Q25: R06-HW2C05-TRS-DVO-CM-0012_C0 | R25: Closed Out | S25: Closed / Agreed | V25: =HYPERLINK("https://ksa1.aconex.com/MiniURL?type=MAILSEARCH&mailbox=5&pid=1342178882&cid=1387862439","View Submission") -> View Submission | Z25: Chamintha
B26: =B25+1 -> 16 | C26: =LEFT(IFERROR("VO-"&_xlfn.TEXTAFTER(P26,"-00"),""),5) -> VO-34 | D26: 45994 | E26: DVO-CM-0034 | F26: Supply and Installation of (Direct-buried type) Valve for Potable Water & Irrigation System | G26: 46005 | H26: VO | I26: FFC06HW2-GENCORR-000519 | J26: FFC06HW2-GENCORR-000519 | L26: 592973.09 | M26: 271543.24 | N26: 271543.24 | O26: DVO Issued | P26: R06-HW2C05-TRS-VOR-CM-0034 | R26: FFC agreed with RSG value; DVO to be processed | U26: =HYPERLINK("https://ksa1.aconex.com/MiniURL?type=MAILSEARCH&mailbox=5&pid=1342178882&cid=1404700558","Open in Aconex") -> Open in Aconex | V26: =HYPERLINK("https://ksa1.aconex.com/MiniURL?type=MAILSEARCH&mailbox=5&pid=1342178882&cid=1405406784","View Submission") -> View Submission | Z26: Aaqil
B27: =B26+1 -> 17 | C27: =LEFT(IFERROR("VO-"&_xlfn.TEXTAFTER(P27,"-00"),""),5) -> VO-09 | D27: 45656 | F27: Omission of FCU's Supplying Kitchen Preparation Rooms in HoH | G27: 45663 | H27: VO | I27: FFC06HW2-GENCORR-000208 | J27: FFC06HW2-GENCORR-000208 | K27: 45787 | L27: -3237.5866 | M27: -3237.5866 | N27: -3237.5866 | O27: DVO Issued | P27: R06-HW2C05-TRS-VOR-CM-0009 | S27: FFC responded dated 6-Aug-25/ RSG to check MIR for the delivered FCU prior to the VO issuance.. | U27: Open in Aconex | V27: =HYPERLINK("https://ksa1.aconex.com/MiniURL?type=MAILSEARCH&mailbox=5&pid=1342178882&cid=1386381111","View Submission") -> View Submission
B28: =B27+1 -> 18 | C28: =LEFT(IFERROR("VO-"&_xlfn.TEXTAFTER(P28,"-00"),""),5) -> VO-55 | D28: 46062 | F28: Creation of Informal Sand Paths for Improved Beach Access | G28: 2/152/2026 | H28: VO | I28: FFC06HW2-GENCORR-000700 | J28: FFC06HW2-GENCORR-000700 | L28: 8394.87 | M28: 5626.23 | N28: =M28 -> 5626.23 | O28: DVO Issued | P28: R06-HW2C05-TRS-VOR-CM-0055 | R28: Documents are submitted officially on ACONEX and wating for RSG Assessment | U28: =HYPERLINK("https://ksa1.aconex.com/MiniURL?type=MAILSEARCH&mailbox=5&pid=1342178882&cid=1408837081","Open in Aconex") -> Open in Aconex | V28: =HYPERLINK("https://ksa1.aconex.com/MiniURL?type=MAILSEARCH&mailbox=5&pid=1342178882&cid=1409155110","View Submission") -> View Submission
B29: =B28+1 -> 19 | C29: =LEFT(IFERROR("VO-"&_xlfn.TEXTAFTER(P29,"-00"),""),5) -> VO-21 | D29: 45881 | F29: Main Pool Bar - Sunken Bar Drain Piping to Waste Network | G29: 45890 | H29: VO | I29: FFC06HW2-GENCORR-000443 | J29: FFC06HW2-GENCORR-000443 | L29: 10039.576 | M29: 2914.77 | N29: =M29 -> 2914.77 | O29: DVO Issued | P29: R06-HW2C05-TRS-VOR-CM-0021_C0 | R29: Closed Out | S29: Closed / Agreed | U29: =HYPERLINK("https://ksa1.aconex.com/MiniURL?type=MAILSEARCH&mailbox=5&pid=1342178882&cid=1397994822","Open in Aconex") -> Open in Aconex | V29: =HYPERLINK("https://ksa1.aconex.com/MiniURL?type=MAILSEARCH&mailbox=5&pid=1342178882&cid=1398537728","View Submission") -> View Submission | X29: Pending with FFC RSG rejects the cost proposal and requested for a revision. The cost is deemed very excessive due to incorrect rates applied. I (e.g RMF Filter, Heat pump, etc.). | Z29: Aaqil
B30: =B29+1 -> 20 | C30: =LEFT(IFERROR("VO-"&_xlfn.TEXTAFTER(P30,"-00"),""),5) -> VO-33 | D30: 45923 | F30: Supply and installation of the required missing kitchen drainage pipelines in the Kitchen Areas at Amenity & HOH buildings | G30: 45941 | H30: VO | I30: FFC06HW2-GENCORR-000463 | J30: FFC06HW2-GENCORR-000463 | L30: 100533.74 | M30: 66373.62 | N30: =M30 -> 66373.62 | O30: DVO Issued | P30: R06-HW2C05-TRS-VOR-CM-0033 | R30: FFC accepted RSG assessment on 12-May-2026 via email | U30: =HYPERLINK("https://ksa1.aconex.com/MiniURL?type=MAILSEARCH&mailbox=5&pid=1342178882&cid=1400421785","Open in Aconex") -> Open in Aconex | V30: =HYPERLINK("https://ksa1.aconex.com/MiniURL?type=MAILSEARCH&mailbox=5&pid=1342178882&cid=1401423017","View Submission") -> View Submission
B31: =B30+1 -> 21 | C31: =LEFT(IFERROR("VO-"&_xlfn.TEXTAFTER(P31,"-00"),""),5) -> VO-45 | D31: 46034 | F31: MEP related works due to the Lifting Station Electrical Panel Relocation | G31: 46065 | H31: VO | I31: FFC06HW2-GENCORR-000681 | J31: FFC06HW2-GENCORR-000681 | L31: 252445.35 | M31: 133704 | N31: =M31 -> 133704 | O31: DVO Issued | P31: R06-HW2C05-TRS-VOR-CM-0045 | R31: FFC accepted RSG assessment on 12-May-2026 via email | U31: =HYPERLINK("https://ksa1.aconex.com/MiniURL?type=MAILSEARCH&mailbox=5&pid=1342178882&cid=1407129869","Open in Aconex") -> Open in Aconex | V31: =HYPERLINK("https://ksa1.aconex.com/MiniURL?type=MAILSEARCH&mailbox=5&pid=1342178882&cid=1408993598","View Submission") -> View Submission
B32: =B55+1 -> 67 | C32: =LEFT(IFERROR("VO-"&_xlfn.TEXTAFTER(P32,"-00"),""),5) -> VO-18 | D32: 45763 | F32: Connection of Pool Overflow Drain to Sump Pit instead of Manhole | G32: 45875 | H32: VO | I32: FFC06HW2-GENCORR-000440 | J32: FFC06HW2-GENCORR-000440 | L32: 194460.1 | M32: 109935.69 | N32: =M32 -> 109935.69 | O32: DVO Issued | P32: R06-HW2C05-TRS-VOR-CM-0018 | R32: Closed Out | S32: Awaiting FFC response | U32: =HYPERLINK("https://ksa1.aconex.com/hub/index.html?mainTarget=%2Frsrc%2F20260529.1112%2Fen_AU_DOC%2Fmail%2Fview%2Findex.html%231342178882%2F1397845857%3Fe2e%3Dnull","Open in Aconex") -> Open in Aconex | V32: =HYPERLINK("https://ksa1.aconex.com/MiniURL?type=MAILSEARCH&mailbox=5&pid=1342178882&cid=1397659597","View Submission") -> View Submission | Z32: Hizam
B33: =B31+1 -> 22 | C33: =LEFT(IFERROR("VO-"&_xlfn.TEXTAFTER(P33,"-00"),""),5) -> VO-11 | D33: 45693 | F33: Omission of Fire Dampers Mounted on 1 Hour Fire Rated Walls | G33: 45871 | H33: VO | I33: FFC06HW2-GENCORR-000250 | J33: FFC06HW2-GENCORR-000250 | L33: -123292.18 | M33: -237846.63 | N33: -237846.63 | O33: DVO RR Issued | P33: R06-HW2C05-TRS-VOR-CM-0011 | R33: Closed Out | S33: Closed / Agreed | V33: =HYPERLINK("https://ksa1.aconex.com/MiniURL?type=MAILSEARCH&mailbox=5&pid=1342178882&cid=1388224710","View Submission") -> View Submission | Z33: Chamintha
B34: =B33+1 -> 23 | C34: =LEFT(IFERROR("VO-"&_xlfn.TEXTAFTER(P34,"-00"),""),5) -> VO-13 | D34: 45698 | F34: Omission of External Emergency Lights above Fire Hose Cabinet | G34: 45703 | H34: VO | I34: FFC06HW2-GENCORR-000260 | J34: FFC06HW2-GENCORR-000260 | L34: -76534.47 | M34: -209293.04 | N34: =M34 -> -209293.04 | O34: DVO RR Issued | P34: R06-HW2C05-TRS-VOR-CM-0013 | R34: DVO RR issued for 131k after they have revised the assesmnet befor they consider BOQ now the considered the drawing we checked the drawing and agreed this value as per drawing | S34: Closed / Agreed | V34: =HYPERLINK("https://ksa1.aconex.com/MiniURL?type=MAILSEARCH&mailbox=5&pid=1342178882&cid=1388618277","View Submission") -> View Submission | Z34: Hizam
B35: =B34+1 -> 24 | C35: =LEFT(IFERROR("VO-"&_xlfn.TEXTAFTER(P35,"-00"),""),5) -> VO-06 | D35: 45652 | F35: Omission of Fire Protection Inside Transformer Rooms | G35: 45894 | H35: VO | I35: FFC06HW2-GENCORR-000211 | J35: FFC06HW2-GENCORR-000445 | K35: 45725 | L35: -30297.49 | M35: -50481.69 | N35: -50481.69 | O35: DVO RR Issued | P35: R06-HW2C05-TRS-VOR-CM-0006 | R35: Closed Out | S35: Closed / Agreed | V35: =HYPERLINK("https://ksa1.aconex.com/MiniURL?type=MAILSEARCH&mailbox=5&pid=1342178882&cid=1386469600","View Submission") -> View Submission | Z35: Hizam
B36: =B35+1 -> 25 | C36: =LEFT(IFERROR("VO-"&_xlfn.TEXTAFTER(P36,"-00"),""),5) -> VO-19 | D36: 45756 | F36: Additional Fire Suppression system in the Signature Restaurant | G36: 45827 | H36: VO | I36: FFC06HW2-GENCORR-000405 | J36: FFC06HW2-GENCORR-000405 | K36: 45858 | L36: 45143.47 | M36: 7557.19 | N36: 7557.19 | O36: DVO RR Issued | P36: R06-HW2C05-TRS-VOR-CM-0019_C0 | R36: Closed Out | S36: Closed / Agreed | U36: =HYPERLINK("https://ksa1.aconex.com/MiniURL?type=MAILSEARCH&mailbox=5&pid=1342178882&cid=1391114597","Open in Aconex") -> Open in Aconex | V36: =HYPERLINK("https://ksa1.aconex.com/MiniURL?type=MAILSEARCH&mailbox=5&pid=1342178882&cid=1394873320","View Submission") -> View Submission
B37: =B36+1 -> 26 | C37: =LEFT(IFERROR("VO-"&_xlfn.TEXTAFTER(P37,"-00"),""),5) -> VO-39 | D37: 45924 | F37: Omit 2Nr. of Inaccessible Wall Sockets (EE-PL38) and Replace with 2Nr Floor Box having 1Nr Outlet (Electrical Provision) at Asset-14 (Children & Teen Center Bldg.) | G37: 45925 | H37: VO | I37: FFC06HW2-GENCORR-000454 | J37: FFC06HW2-GENCORR-000454 | L37: 3242.53 | M37: 1066.52 | N37: 1066.52 | O37: DVO RR Issued | P37: R06-HW2C05-TRS-VOR-CM-0039 | R37: Documents are submitted officially on ACONEX wating for RSG Assessment | U37: =HYPERLINK("https://ksa1.aconex.com/MiniURL?type=MAILSEARCH&mailbox=5&pid=1342178882&cid=1400471683","Open in Aconex") -> Open in Aconex | V37: =HYPERLINK("https://ksa1.aconex.com/MiniURL?type=MAILSEARCH&mailbox=5&pid=1342178882&cid=1400547281","View Submission") -> View Submission | Z37: Chaminda
B38: =B37+1 -> 27 | C38: =LEFT(IFERROR("VO-"&_xlfn.TEXTAFTER(P38,"-00"),""),5) -> VO-32 | D38: 45923 | F38: Simplification of Pools Channel Detailing in 10 nr 3 Bedroom Villa Pools | G38: 45935 | H38: VO | I38: FFC06HW2-GENCORR-000456 | J38: FFC06HW2-GENCORR-000456 | L38: 18314.8 | M38: 7667.65 | N38: =M38 -> 7667.65 | O38: DVO RR Issued | P38: R06-HW2C05-TRS-VOR-CM-0032 | R38: FFC accepted RSG assessment on 12-May-2026 via email | U38: =HYPERLINK("https://ksa1.aconex.com/MiniURL?type=MAILSEARCH&mailbox=5&pid=1342178882&cid=1400421230","Open in Aconex") -> Open in Aconex | V38: =HYPERLINK("https://ksa1.aconex.com/MiniURL?type=MAILSEARCH&mailbox=5&pid=1342178882&cid=1401081896","View Submission") -> View Submission | Z38: Chamintha
B39: =B38+1 -> 28 | C39: =LEFT(IFERROR("VO-"&_xlfn.TEXTAFTER(P39,"-00"),""),5) -> VO-28 | D39: 45853 | F39: MEP provisions related to the cocoon water feature in the reception area of the Arrival building (Asset-10). | G39: 45977 | H39: VO | I39: FFC06HW2-GENCORR-000506 | J39: FFC06HW2-GENCORR-000506 | L39: 300617.66 | M39: 154638.39 | N39: 154638.39 | O39: DVO RR Issued | P39: R06-HW2C05-TRS-VOR-CM-0028 | U39: =HYPERLINK("https://ksa1.aconex.com/MiniURL?type=MAILSEARCH&mailbox=5&pid=1342178882&cid=1396406699","Open in Aconex") -> Open in Aconex | V39: =HYPERLINK("https://ksa1.aconex.com/MiniURL?type=MAILSEARCH&mailbox=5&pid=1342178882&cid=1403594774","View Submission") -> View Submission | Z39: Chamintha
B40: =B39+1 -> 29 | C40: =LEFT(IFERROR("VO-"&_xlfn.TEXTAFTER(P40,"-00"),""),5) -> VO-16 | D40: 45676 | F40: Reduction of the primary irrigation loop along with Points of Connections (POCs) | G40: 45691 | H40: VO | I40: FFC06HW2-GENCORR-000246 | J40: FFC06HW2-GENCORR-000246 | K40: 45830 | L40: 81086.98 | M40: -35608.362 | N40: =M40 -> -35608.362 | O40: DVO RR Issued | P40: R06-HW2C05-TRS-VOR-CM-0016 | R40: Agreed and replied | S40: Awaiting FFC response | U40: =HYPERLINK("https://ksa1.aconex.com/MiniURL?type=MAILSEARCH&mailbox=5&pid=1342178882&cid=1387043564","Open in Aconex") -> Open in Aconex | V40: =HYPERLINK("https://ksa1.aconex.com/MiniURL?type=MAILSEARCH&mailbox=5&pid=1342178882&cid=1387914566","View Submission") -> View Submission | X40: FFC | Z40: Hassan
B41: =B40+1 -> 30 | C41: =LEFT(IFERROR("VO-"&_xlfn.TEXTAFTER(P41,"-00"),""),5) -> VO-17 | D41: 45727 | F41: Modification to Telephone Operator Room in HOH (Asset 60) | G41: 45735 | H41: VO | I41: FFC06HW2-GENCORR-000306 | J41: FFC06HW2-GENCORR-000306 | L41: 3871.55 | M41: 3871.53 | N41: 3871.53 | O41: Approved , Pending DVO | P41: R06-HW2C05-TRS-VOR-CM-0017_C0 | R41: Accepted Waiting For DVO | U41: Open in Aconex | V41: =HYPERLINK("https://ksa1.aconex.com/MiniURL?type=MAILSEARCH&mailbox=5&pid=1342178882&cid=1390330845","View Submission") -> View Submission | Z41: Hassan
B42: =B41+1 -> 31 | C42: =LEFT(IFERROR("VO-"&_xlfn.TEXTAFTER(P42,"-00"),""),5) -> VO-24 | D42: 45846 | F42: Provision of electrical power connection on motorised roller shutter in the kitchen areas at HOH (Asset 60) | G42: 45855 | H42: VO | I42: FFC06HW2-GENCORR-000414 | J42: FFC06HW2-GENCORR-000414 | K42: 45857 | L42: 7984.66 | M42: 1659.95 | N42: 1659.95 | O42: Approved , Pending DVO | P42: R06-HW2C05-TRS-VOR-CM-0024 | R42: Approved Awaiting for DVO | S42: Awaiting FFC response | U42: =HYPERLINK("https://ksa1.aconex.com/MiniURL?type=MAILSEARCH&mailbox=5&pid=1342178882&cid=1395981199","Open in Aconex") -> Open in Aconex | V42: =HYPERLINK("https://ksa1.aconex.com/MiniURL?type=MAILSEARCH&mailbox=5&pid=1342178882&cid=1396532517","View Submission") -> View Submission
B43: =B42+1 -> 32 | C43: =LEFT(IFERROR("VO-"&_xlfn.TEXTAFTER(P43,"-00"),""),5) -> VO-35 | D43: 45913 | F43: SPA - Addition of Missed Small Power and Data Requirements | G43: 15-10-20255 | H43: VO | I43: FFC06HW2-GENCORR-000488 | J43: FFC06HW2-GENCORR-000488 | L43: 15738.35 | M43: 14162.59 | N43: 14162.59 | O43: Approved , Pending DVO | P43: R06-HW2C05-TRS-VOR-CM-0035 | R43: FFC Repied to RSG Comments | U43: =HYPERLINK("https://ksa1.aconex.com/MiniURL?type=MAILSEARCH&mailbox=5&pid=1342178882&cid=1399833363","Open in Aconex") -> Open in Aconex | V43: =HYPERLINK("https://ksa1.aconex.com/MiniURL?type=MAILSEARCH&mailbox=5&pid=1342178882&cid=1401721317","View Submission") -> View Submission
...

Sheet Sheet1
A1: Pending with FFC | D1: =COUNTIFS('VO LOG (2)'!$O$11:$O$119,A1) -> 9 | E1: {=SUMIFS('VO LOG (2)'!N:N,'VO LOG (2)'!O:O,Sheet1!A1:A6)} -> 0 | G1: ='VO LOG (2)'!$M$5 -> 0
A2: Pending with RSG | D2: =COUNTIFS('VO LOG (2)'!$O$11:$O$119,A2) -> 22 | E2: 2991535.6 | G2: =E1+E2+E3 -> 9676283.7
A3: Pending with RSG/FFC | D3: =COUNTIFS('VO LOG (2)'!$O$11:$O$119,A3) -> 4 | E3: 6684748.2
A4: ='VO LOG (2)'!X14 -> Approved , Pending DVO | D4: =COUNTIFS('VO LOG (2)'!$O$11:$O$119,A4) -> 18 | E4: -23074.749
A5: DVO RR Issued | D5: =COUNTIFS('VO LOG (2)'!$O$11:$O$119,A5) -> 8 | E5: -362299.97
A6: DVO Issued | D6: =COUNTIFS('VO LOG (2)'!$O$11:$O$119,A6) -> 22 | E6: 15744723
A7: Total Submitted VO | D7: =D5+D4+D2+D3+D6 -> 74 | E7: =SUM(_xlfn.ANCHORARRAY(E1)) -> 25035632

Sheet Sheet2
A1: PAYMENT REGISTER-HW2C05
A2: PROJECT DETAILS
A3: Project: | B3: R06-HW2C05-5020
A4: Contractor: | B4: First Fix
A5: Currancy SAR
A6: Summary of IPA's (without VAT) | F6: `
A8: Original Contract Value | B8: 2.1750156e+08
A9: Revised Contract Value | B9: 2.3270841e+08
A10: PAYMENT STATUS | Q10: .
B11: Gross amount | D11: Net amount
A12: Under Review | B12: 12000000 | C12: 0.06 | D12: =(D13/B13)*B12 -> 8771580
A13: Submitted on ACONEX | B13: 6418102.4 | C13: 0.077371738 | D13: {='Payment Register'!J40:J41} -> 4691408.2
A14: Approved via Acconex | B14: 18005054 | C14: 0.027580019 | D14: 13161064
A15: Received | B15: 1.4884701e+08 | C15: 0.63962885 | D15: =SUM('Payment Register'!J19:J39) -> 1.1403222e+08
A17: Total Work Done | B17: 1.7327017e+08 | C17: 0.74458061 | D17: =SUM('Payment Register'!J19:J41) -> 1.3188469e+08
A18: Balance Work Done | B18: 59438241 | C18: 0.25541939 | D18: 54239999
A20: SUMMARY OF ADVANCE PAYMENT RECOVERY IPA
A21: Advance Payment | B21: 65250467 | C21: 0.3209
A22: Deducted till Date | B22: 51054339 | C22: 0.78243638
A23: Balance | B23: 14196128 | C23: 0.21756362
A25: SUMMARY OF RETENTION IPA
A26: Total Retention | B26: 10875078 | C26: 0.05
A27: Deducted till Date | B27: 8663508.4 | C27: 0.79663875
A28: Balance | B28: 2211569.4 | C28: 0.20336125
B30: VO STATUS
B31: Pending with FFC | C31: 1 | D31: 45000
B32: Pending with RSG | C32: 27 | D32: 11680021
B33: Pending with RSG/FFC | C33: 9 | D33: 4136961.4
B34: Approved & Awaiting for the DVO to be issued | C34: 3 | D34: -113950.17
B35: DVO RR Issued | C35: 10 | D35: 15320803
B36: Total Submitted VO | C36: 49 | D36: 31023835

Sheet VO LOG (New)
B2: VARIATION ORDER LOG
B3: HW2 MEP | Pay Reg & VO Tracking | O3: =TODAY() -> 46232
B6: TOTAL VOs | D6: DVO ISSUED | F6: APPROVED | H6: PENDING RSG/FFC | J6: PENDING RSG | L6: PENDING FFC | N6: APPROVED VALUE | S6: Status | T6: Count
B7: =#REF! -> #REF! | D7: =#REF! -> #REF! | F7: =#REF! -> #REF! | H7: =#REF! -> #REF! | J7: =#REF! -> #REF! | L7: =#REF! -> #REF! | N7: =#REF! -> #REF! | S7: DVO Issued | T7: =#REF! -> #REF!
B8: Submitted | D8: Closed Out | F8: Awaiting DVO | H8: Joint Review | J8: Under Assessment | L8: Action Required | N8: SAR Total | S8: Approved | T8: =#REF! -> #REF!
S9: Pending RSG/FFC | T9: =#REF! -> #REF!
B10: # | C10: SUBJECT | D10: TYPE | E10: SUBMITTED | F10: COST PROPOSAL | G10: RSG ASSESSMENT | H10: FINAL APPROVED | I10: STATUS | J10: VOR REF | K10: DVO REF | L10: SUBMISSION REF | M10: FFC REMARKS | N10: LIVE ACTION | O10: RSG REMARKS | P10: ASSIGNED | S10: Pending RSG | T10: =#REF! -> #REF!
C11: ✅ DVO RR ISSUED | H11: 19 items | S11: Pending FFC | T11: =#REF! -> #REF!
B12: 1 | C12: =#REF! -> #REF! | D12: =#REF! -> #REF! | E12: =#REF! -> #REF! | F12: =#REF! -> #REF! | G12: =#REF! -> #REF! | H12: =#REF! -> #REF! | I12: =#REF! -> #REF! | J12: =#REF! -> #REF! | ... P12: =#REF! -> #REF!
B13: 2 | C13: =#REF! -> #REF! | D13: =#REF! -> #REF! | E13: =#REF! -> #REF! | F13: =#REF! -> #REF! | G13: =#REF! -> #REF! | H13: =#REF! -> #REF! | I13: =#REF! -> #REF! | J13: =#REF! -> #REF! | ... P13: =#REF! -> #REF!
B14: 3 | C14: =#REF! -> #REF! | D14: =#REF! -> #REF! | E14: =#REF! -> #REF! | F14: =#REF! -> #REF! | G14: =#REF! -> #REF! | H14: =#REF! -> #REF! | I14: =#REF! -> #REF! | J14: =#REF! -> #REF! | ... P14: =#REF! -> #REF!
B15: 4 | C15: =#REF! -> #REF! | D15: =#REF! -> #REF! | E15: =#REF! -> #REF! | F15: =#REF! -> #REF! | G15: =#REF! -> #REF! | H15: =#REF! -> #REF! | I15: =#REF! -> #REF! | J15: =#REF! -> #REF! | ... P15: =#REF! -> #REF!
B16: 5 | C16: =#REF! -> #REF! | D16: =#REF! -> #REF! | E16: =#REF! -> #REF! | F16: =#REF! -> #REF! | G16: =#REF! -> #REF! | H16: =#REF! -> #REF! | I16: =#REF! -> #REF! | J16: =#REF! -> #REF! | ... P16: =#REF! -> #REF!
B17: 6 | C17: =#REF! -> #REF! | D17: =#REF! -> #REF! | E17: =#REF! -> #REF! | F17: =#REF! -> #REF! | G17: =#REF! -> #REF! | H17: =#REF! -> #REF! | I17: =#REF! -> #REF! | J17: =#REF! -> #REF! | ... P17: =#REF! -> #REF!
B18: 7 | C18: =#REF! -> #REF! | D18: =#REF! -> #REF! | E18: =#REF! -> #REF! | F18: =#REF! -> #REF! | G18: =#REF! -> #REF! | H18: =#REF! -> #REF! | I18: =#REF! -> #REF! | J18: =#REF! -> #REF! | ... P18: =#REF! -> #REF!
B19: 8 | C19: =#REF! -> #REF! | D19: =#REF! -> #REF! | E19: =#REF! -> #REF! | F19: =#REF! -> #REF! | G19: =#REF! -> #REF! | H19: =#REF! -> #REF! | I19: =#REF! -> #REF! | J19: =#REF! -> #REF! | ... P19: =#REF! -> #REF!
B20: 9 | C20: =#REF! -> #REF! | D20: =#REF! -> #REF! | E20: =#REF! -> #REF! | F20: =#REF! -> #REF! | G20: =#REF! -> #REF! | H20: =#REF! -> #REF! | I20: =#REF! -> #REF! | J20: =#REF! -> #REF! | ... P20: =#REF! -> #REF!
B21: 10 | C21: =#REF! -> #REF! | D21: =#REF! -> #REF! | E21: =#REF! -> #REF! | F21: =#REF! -> #REF! | G21: =#REF! -> #REF! | H21: =#REF! -> #REF! | I21: =#REF! -> #REF! | J21: =#REF! -> #REF! | ... P21: =#REF! -> #REF!
B22: 11 | C22: =#REF! -> #REF! | D22: =#REF! -> #REF! | E22: =#REF! -> #REF! | F22: =#REF! -> #REF! | G22: =#REF! -> #REF! | H22: =#REF! -> #REF! | I22: =#REF! -> #REF! | J22: =#REF! -> #REF! | ... P22: =#REF! -> #REF!
B23: 12 | C23: =#REF! -> #REF! | D23: =#REF! -> #REF! | E23: =#REF! -> #REF! | F23: =#REF! -> #REF! | G23: =#REF! -> #REF! | H23: =#REF! -> #REF! | I23: =#REF! -> #REF! | J23: =#REF! -> #REF! | ... P23: =#REF! -> #REF!
... B30: 19 | C30: =#REF! -> #REF! | D30: =#REF! -> #REF! | E30: =#REF! -> #REF! | F30: =#REF! -> #REF! | G30: =#REF! -> #REF! | H30: =#REF! -> #REF! | I30: =#REF! -> #REF! | J30: =#REF! -> #REF! | ... P30: =#REF! -> #REF!
C31: 🔵 APPROVED — AWAITING DVO | H31: 6 items
B32: 20 | C32: =#REF! -> #REF! | D32: =#REF! -> #REF! | E32: =#REF! -> #REF! | F32: =#REF! -> #REF! | G32: =#REF! -> #REF! | H32: =#REF! -> #REF! | I32: =#REF! -> #REF! | J32: =#REF! -> #REF! | ... P32: =#REF! -> #REF!
B33: 21 | C33: =#REF! -> #REF! | D33: =#REF! -> #REF! | E33: =#REF! -> #REF! | F33: =#REF! -> #REF! | G33: =#REF! -> #REF! | H33: =#REF! -> #REF! | I33: =#REF! -> #REF! | J33: =#REF! -> #REF! | ... P33: =#REF! -> #REF!
B34: 22 | C34: =#REF! -> #REF! | D34: =#REF! -> #REF! | E34: =#REF! -> #REF! | F34: =#REF! -> #REF! | G34: =#REF! -> #REF! | H34: =#REF! -> #REF! | I34: =#REF! -> #REF! | J34: =#REF! -> #REF! | ... P34: =#REF! -> #REF!
B35: 23 | C35: =#REF! -> #REF! | D35: =#REF! -> #REF! | E35: =#REF! -> #REF! | F35: =#REF! -> #REF! | G35: =#REF! -> #REF! | H35: =#REF! -> #REF! | I35: =#REF! -> #REF! | J35: =#REF! -> #REF! | ... P35: =#REF! -> #REF!
B36: 24 | C36: =#REF! -> #REF! | D36: =#REF! -> #REF! | E36: =#REF! -> #REF! | F36: =#REF! -> #REF! | G36: =#REF! -> #REF! | H36: =#REF! -> #REF! | I36: =#REF! -> #REF! | J36: =#REF! -> #REF! | ... P36: =#REF! -> #REF!
B37: 25 | C37: =#REF! -> #REF! | D37: =#REF! -> #REF! | E37: =#REF! -> #REF! | F37: =#REF! -> #REF! | G37: =#REF! -> #REF! | H37: =#REF! -> #REF! | I37: =#REF! -> #REF! | J37: =#REF! -> #REF! | ... P37: =#REF! -> #REF!
C38: 🟡 PENDING WITH RSG/FFC | H38: 10 items
B39: 26 | C39: =#REF! -> #REF! | D39: =#REF! -> #REF! | E39: =#REF! -> #REF! | F39: =#REF! -> #REF! | G39: =#REF! -> #REF! | H39: =#REF! -> #REF! | I39: =#REF! -> #REF! | J39: =#REF! -> #REF! | ... P39: =#REF! -> #REF!
